Workbook

Sheet README
A1: Mech Arena Database — How To Read This Sheet
A3: This workbook is the community-verified database that powers ArenaBot. It's split into 10 tabs. The four "stat" tabs (Mechs, Weapons, Pilots, Mods) hold identity and gameplay info — one row per item. The four "Upgrade Costs" tabs are shared reference tables — one row per rarity tier per upgrade step, not per item, because the game charges the same upgrade cost to every item of the same rarity (and, for weapons, the same energy level).
A5: TAB-BY-TAB GUIDE
A7: Mechs | B7: One row per mech (46 total). Stats, ability, strengths/weaknesses, and Unlock Cost — what it costs to unlock the mech itself, separate from upgrading it afterward.
A8: Weapons | B8: One row per weapon energy variant (251 total). E.g. "Storm Rack" appears as several rows — Storm Rack 6, Storm Rack 8, Storm Rack 12 — because each energy version has different stats and a different unlock cost. "Base Name" groups the variants together.
A9: Pilots | B9: One row per pilot (36 total). Skill/weapon specialty and the HP/DMG % bonus they grant.
A10: Mods | B10: One row per mod (14 total). Effect description and base purchase cost.
A12: Mech Upgrade Costs | B12: How much it costs to level up a mech from Star X Level Y to the next step — Credits, A-Coins, and Blueprints needed. This is NOT one row per mech — it's one row per rarity tier (7 tiers) per star/level (42 steps) = 294 rows, because a Common mech and every other Common mech cost the same to upgrade.
A13: Weapon Upgrade Costs | B13: Same idea as above but for weapons — one row per rarity+energy combination (37 of them) per star/level step = 1,554 rows.
A14: Pilot Upgrade Costs | B14: Same idea — one row per rarity (Rare/Epic/Legendary) per star/level step. Costs are in A-Coins, Marks, and XP instead of Credits/Blueprints.
A15: Mod Upgrade Costs | B15: One row per mod per level (2 through 6). Costs are in Basic Mod Parts and Elite Mod Parts.
A17: Best Builds | B17: Community-submitted mech + weapon loadouts.
A18: Meta | B18: The current top-ranked builds, in order.
A20: HOW TO LOOK UP AN UPGRADE COST — WORKED EXAMPLE
A22: Say you want to know what it costs to upgrade Aegis to Star 2, Level 1.
A23: Step 1 — Go to the Mechs tab, find "Aegis", and read its Rarity Key column. It says: epic_b_mech
A24: Step 2 — Go to the Mech Upgrade Costs tab. Filter/search for Rarity Key = epic_b_mech AND Star = 2 AND Level = 1.
A25: Step 3 — That row shows the Credits, A-Coins, and Blueprints needed for that single step.
A27: Weapons work the same way, just with the Weapon's Rarity Key (which also encodes energy, e.g. epic_b_weapon_6) against the Weapon Upgrade Costs tab.
A29: Mods work the same way using the Cost Table Key column on the Mods tab (e.g. epic_perimeter_ml) against the Mod Upgrade Costs tab.
A31: WHAT THE "RARITY KEY" / "COST TABLE KEY" COLUMNS MEAN
A33: These are just the item's Rarity (and Energy, for weapons) written in one lowercase, underscore-joined string — it exists purely so this key can be matched exactly against the Upgrade Costs tabs. You never need to type or edit it; it's generated from the Rarity and Energy columns already on that row.
A35: ABBREVIATIONS
A37: A-Coins | B37: In-game premium-ish currency (sometimes shown as "ACoins").
A38: Credits | B38: Basic in-game currency, earned freely through play.
A39: Blueprints | B39: Item-specific currency needed (alongside Credits) to star-up a mech or weapon.
A40: Marks | B40: Pilot-upgrade currency.
A41: XP | B41: Pilot experience points, spent on pilot leveling.
A42: Basic / Elite Mod Parts | B42: Currencies used to level up mods.
A43: Star / Level | B43: Mech Arena's two-axis upgrade system — an item levels up (1→Max) within a Star, then Star-ups reset the level and raise the power ceiling.
A45: DATA QUALITY NOTES
A47: Mechs, Weapons, and all four Upgrade Costs tabs come directly from the official community database (mecharenadev.com) and are treated as verified/authoritative.
A48: Pilots and Mods are filled in manually by the team. Check the "Verified" column on those two tabs before trusting a row — "Pending" or "Needs Review" means it hasn't been confirmed in-game yet. A few Mods rows are still blank (e.g. Perimeter's effect description) and are waiting on someone to fill them in.

Sheet Calculator
A1: Upgrade Cost Calculator
A2: Pick an item and a From/To Star+Level (or From/To Level for Mods). Totals below update automatically. Grey input cells are the only cells you should edit.
A4: MECH UPGRADE CALCULATOR
A5: Mech name
A6: From Star | B6: 1 | C6: From Level | D6: 1
A7: To Star | B7: 1 | C7: To Level | D7: 2
A8: Matched rarity key | B8: =IFERROR(INDEX(Mechs!$R$2:$R$47,MATCH(B5,Mechs!$B$2:$B$47,0)),"not found")
A9: TOTAL NEEDED | B9: Credits | C9: A-Coins | D9: Blueprints
B10: =SUMIFS('Mech Upgrade Costs'!$D$2:$D$295,'Mech Upgrade Costs'!$A$2:$A$295,B8,'Mech Upgrade Costs'!$G$2:$G$295,">"&((B6-1)*7+D6),'Mech Upgrade Costs'!$G$2:$G$295,"<="&((B7-1)*7+D7)) | C10: =SUMIFS('Mech Upgrade Costs'!$E$2:$E$295,'Mech Upgrade Costs'!$A$2:$A$295,B8,'Mech Upgrade Costs'!$G$2:$G$295,">"&((B6-1)*7+D6),'Mech Upgrade Costs'!$G$2:$G$295,"<="&((B7-1)*7+D7)) | D10: =SUMIFS('Mech Upgrade Costs'!$F$2:$F$295,'Mech Upgrade Costs'!$A$2:$A$295,B8,'Mech Upgrade Costs'!$G$2:$G$295,">"&((B6-1)*7+D6),'Mech Upgrade Costs'!$G$2:$G$295,"<="&((B7-1)*7+D7))
A12: WEAPON UPGRADE CALCULATOR
A13: Weapon name (incl. energy)
A14: From Star | B14: 1 | C14: From Level | D14: 1
A15: To Star | B15: 1 | C15: To Level | D15: 2
A16: Matched rarity key | B16: =IFERROR(INDEX(Weapons!$AE$2:$AE$252,MATCH(B13,Weapons!$B$2:$B$252,0)),"not found")
A17: TOTAL NEEDED | B17: Credits | C17: A-Coins | D17: Blueprints
B18: =SUMIFS('Weapon Upgrade Costs'!$D$2:$D$1555,'Weapon Upgrade Costs'!$A$2:$A$1555,B16,'Weapon Upgrade Costs'!$G$2:$G$1555,">"&((B14-1)*7+D14),'Weapon Upgrade Costs'!$G$2:$G$1555,"<="&((B15-1)*7+D15)) | C18: =SUMIFS('Weapon Upgrade Costs'!$E$2:$E$1555,'Weapon Upgrade Costs'!$A$2:$A$1555,B16,'Weapon Upgrade Costs'!$G$2:$G$1555,">"&((B14-1)*7+D14),'Weapon Upgrade Costs'!$G$2:$G$1555,"<="&((B15-1)*7+D15)) | D18: =SUMIFS('Weapon Upgrade Costs'!$F$2:$F$1555,'Weapon Upgrade Costs'!$A$2:$A$1555,B16,'Weapon Upgrade Costs'!$G$2:$G$1555,">"&((B14-1)*7+D14),'Weapon Upgrade Costs'!$G$2:$G$1555,"<="&((B15-1)*7+D15))
A20: PILOT UPGRADE CALCULATOR
A21: Pilot name
A22: From Star | B22: 1 | C22: From Level | D22: 1
A23: To Star | B23: 1 | C23: To Level | D23: 2
A24: Matched rarity | B24: =LOWER(IFERROR(INDEX(Pilots!$C$2:$C$37,MATCH(B21,Pilots!$B$2:$B$37,0)),"not found"))
A25: TOTAL NEEDED | B25: A-Coins | C25: Marks | D25: XP
B26: =SUMIFS('Pilot Upgrade Costs'!$D$2:$D$127,'Pilot Upgrade Costs'!$A$2:$A$127,B24,'Pilot Upgrade Costs'!$G$2:$G$127,">"&((B22-1)*7+D22),'Pilot Upgrade Costs'!$G$2:$G$127,"<="&((B23-1)*7+D23)) | C26: =SUMIFS('Pilot Upgrade Costs'!$E$2:$E$127,'Pilot Upgrade Costs'!$A$2:$A$127,B24,'Pilot Upgrade Costs'!$G$2:$G$127,">"&((B22-1)*7+D22),'Pilot Upgrade Costs'!$G$2:$G$127,"<="&((B23-1)*7+D23)) | D26: =SUMIFS('Pilot Upgrade Costs'!$F$2:$F$127,'Pilot Upgrade Costs'!$A$2:$A$127,B24,'Pilot Upgrade Costs'!$G$2:$G$127,">"&((B22-1)*7+D22),'Pilot Upgrade Costs'!$G$2:$G$127,"<="&((B23-1)*7+D23))
A28: MOD UPGRADE CALCULATOR
A29: Mod name
A30: From Level | B30: 1 | C30: To Level | D30: 2
A31: Matched cost key | B31: =IFERROR(INDEX(Mods!$L$2:$L$15,MATCH(B29,Mods!$B$2:$B$15,0)),"not found")
A32: TOTAL NEEDED | B32: Basic Mod Parts | C32: Elite Mod Parts
B33: =SUMIFS('Mod Upgrade Costs'!$C$2:$C$71,'Mod Upgrade Costs'!$A$2:$A$71,B31,'Mod Upgrade Costs'!$B$2:$B$71,">"&B30,'Mod Upgrade Costs'!$B$2:$B$71,"<="&D30) | C33: =SUMIFS('Mod Upgrade Costs'!$D$2:$D$71,'Mod Upgrade Costs'!$A$2:$A$71,B31,'Mod Upgrade Costs'!$B$2:$B$71,">"&B30,'Mod Upgrade Costs'!$B$2:$B$71,"<="&D30)

Sheet Mechs
A1: Mech ID | B1: Name | C1: Rarity | D1: Role | E1: Tier | F1: Max HP | G1: Max Speed | H1: Max Energy | I1: Power | J1: Ability Name | K1: Ability Description | L1: Ability Stats | M1: Strengths | N1: Weaknesses | O1: Reasoning | P1: Unlock Cost | Q1: Unlock Currency | R1: Rarity Key
A2: M001 | B2: Aegis | C2: Epic B | D2: Tank | E2: A | F2: 215,100 | G2: 20 | H2: 24 | I2: 953 | J2: Dome Shield | K2: Circular dome blocking attacks and most abilities from outside and above. | L2: Ability Cooldown: 10 s | Ability Duration: 10 s | Dome Radius: 10 m | Dome Durability: 750,000 | M2: Protects the whole team. | N2: Medium speed. | O2: The dome is one of the strongest team-play abilities in the game, completely blocking incoming fire for the whole team. High HP for an Epic. Drops to A rather than S only because it requires coordination to use well. | P2: 1865 | Q2: A-Coins | R2: epic_b_mech
A3: M002 | B3: Arachnos | C3: Rare | D3: Support | E3: D | F3: 120,600 | G3: 14 | H3: 32 | I3: 762 | J3: Spider Turret | K3: Spider Turret — Deploys a small destructible turret that activates and attacks when an enemy approaches. | L3: Ability Cooldown: 22 s | Turret Damage: 351 | Turret Active Lifetime: 10 s | Arachnos Turret Range: 30 m | M3: High energy capacity; passive area denial. | N3: Slowest mech; negligible turret damage; very long cooldown; very low HP. | O3: Tied for the slowest mech in the game at 14 km/h, making it nearly immobile in dynamic fights. The turret deals trivial damage (351 at max), has a 22s cooldown, and can be destroyed instantly. High energy capacity is the only redeeming quality. | P3: 42200 | Q3: Credits | R3: rare_mech
A4: M003 | B4: Ares | C4: Rare | D4: Tank | E4: B | F4: 160,800 | G4: 18 | H4: 24 | I4: 857 | J4: Wide Shield | K4: Wide Shield — Activates a portable shield that protects the Mech and nearby allies from enemy fire. | L4: Ability Cooldown: 12 s | Shield Durability: 43,900 | M4: Shield covers allies; always active while up; good energy capacity. | N4: Lower HP than Epic/Legendary tanks; no offensive element. | O4: The team coverage sets Ares apart from Juggernaut — protecting allies as well as itself is meaningful in grouped play. Decent HP for a Rare and good energy. Held back by moderate durability and no offensive component. | P4: 420 | Q4: A-Coins | R4: rare_mech
A5: M004 | B5: Bastion | C5: Legendary | D5: Tank | E5: A | F5: 284,100 | G5: 18 | H5: 24 | I5: 1,083 | J5: Blast Shield | K5: Side shield that explodes and EMPs when destroyed. | L5: Ability Cooldown: 16 s | Shield Durability: 60,000 | Shield Damage Radius: 30 m | Blast Shield Damage: 22,700 | Blast Shield EMP Duration: 3 s | M5: Extremely high HP. | N5: Slow. | O5: Highest HP in the game and EMP on shield destruction. However, 18 km/h means it cannot reposition or contest objectives effectively — it is a static anchor that skilled opponents simply flank around. | P5: 9375 | Q5: A-Coins | R5: legendary_mech
A6: M005 | B6: Blizzfrost | C6: Legendary | D6: Scout | E6: S | F6: 181,800 | G6: 29 | H6: 24 | I6: 962 | J6: Icy Grip | K6: Icy Grip — Creates a freeze zone dealing damage. Frozen enemies cannot move; each frozen enemy reduces damage taken. Stasis immunity while active. | L6: Ability Cooldown: 7 s | Ability Duration: 5 s | Icy Grip Radius: 30 m | Icy Grip Damage: 50,000 | Speed Boost: +20% | DMG Reduction (Base): 50% | DMG Reduction (Per Mech): 12.5% | M6: Largest AoE of any scout; damage reduction scales per frozen enemy; Stasis immunity. | N6: None. | O6: One of the strongest abilities in the game. Massive 30m AoE, 50k damage, movement denial, and a damage reduction that stacks per frozen enemy — effectively near-immortal in team fights. Stasis immunity prevents the obvious counter. | Q6: Paid | R6: legendary_mech
A7: M006 | B7: Blockhorn | C7: Legendary | D7: Tank | E7: A | F7: 227,300 | G7: 19 | H7: 32 | I7: 948 | J7: Barricade | K7: Barricade — Deploys an impassable barrier blocking enemy fire and most abilities; boosts ally damage behind it. | L7: Ability Cooldown: 9 s | Ability Duration: 7 s | Barricade Durability: 503,100 | Barricade Amp Zone Damage: +30% | Barricade Amp Zone Size: 11.5 x 10 m² | M7: Impassable barrier; boosts ally damage; blocks most abilities; high energy cap. | N7: Static; can be flanked; requires team coordination. | O7: The Barricade has extraordinary durability (503k at max rank) and the Amp Zone behind it creates a powerful forward push position for teammates. High energy capacity and good HP for an Epic. Requires team coordination to fully exploit. | P7: 9375 | Q7: A-Coins | R7: legendary_mech
A8: M007 | B8: Brickhouse | C8: Legendary | D8: Support | E8: B | F8: 241,500 | G8: 14 | H8: 24 | I8: 1,033 | J8: Overcharger | K8: Overcharger — Boosts damage for self and nearby allies. | L8: Ability Cooldown: 12 s | Ability Duration: 10s | Mech Bonus Damage: +50% | Team Bonus Damage: +100% | Overcharger Radius: 10m | M8: Massive ally damage boost in radius; high HP. | N8: Slowest mech; tiny radius; team buff rarely applies in practice. | O8: The +100% team damage buff is among the strongest damage multipliers in the game but the 14 km/h speed and tiny 10m radius make it extremely difficult to apply to teammates in real matches. Usually only reliably buffs itself. | P8: 937500 | Q8: Credits | R8: legendary_mech
A9: M008 | B9: Cheetah | C9: Epic A | D9: Support | E9: D | F9: 131,400 | G9: 22 | H9: 16 | I9: 872 | J9: Mines | K9: Places up to 3 mines that explode when an enemy comes close. | L9: Ability Cooldown: 6 s | Ability Damage: 38,000 | Mine Damage Radius: 12 m | M9: Very high burst damage from mines. | N9: Relatively slow and not durable. Ability is easily avoidable when paying attention to the ground. | O9: Low HP, mid energy, mid speed. Strong damage ability but very easily avoidable. | P9: 1305 | Q9: A-Coins | R9: epic_a_mech
A10: M009 | B10: Citadel | C10: Legendary | D10: Support | E10: S | F10: 269,900 | G10: 19 | H10: 24 | I10: 1,066 | J10: Seismic Field | K10: Seismic Field — Creates a zone slowing and blocking movement of enemies. Citadel gains speed and a scaling shield. Reduces status effect duration on Citadel. | L10: Ability Cooldown: 10 s | Ability Duration: 8 s | Seismic Field Size: 20 x 13 m² | Citadel Shield Durability: 123,400 | Bonus Shield Durability: 47,500 | Enemy Speed Reduction: -60% | Citadel Speed Increase: +60% | Status Effect Reduction: -75% | M10: High HP support; slows enemies and blocks movement abilities; scaling shield; status effect resistance; speed boost during ability. | N10: Self-focused ability; needs enemies in zone for full shield value. | O10: One of the most layered support abilities in the game. High HP for a support, decent base speed that surges during ability, a massive self-scaling shield, enemy movement denial, and near-immunity to status effects. Excels in both team fights and 1v1. | Q10: Paid | R10: legendary_mech
A11: M010 | B11: Deathwalker | C11: Legendary | D11: Tank | E11: S | F11: 227,300 | G11: 19 | H11: 32 | I11: 948 | J11: Reanimate | K11: Sets a resurrect point, gains +60% speed. If destroyed while the ability is active it resurrects at the point it set with 105% of its HP before ability activation. Cooldown: 15s. | L11: Ability Cooldown: 15 s | Ability Duration: 15 s | Invulnerability Duration: 3 s | Speed Boost: +60% | HP Restoration: 5% | M11: Resurrection with speed boost is still a powerful defensive ability; strong HP and energy. | N11: Slow base speed without ability; 15s cooldown creates longer exposure windows; only restores 5% above pre-ability HP. | O11: Very effective at rushing directly into the enemy lines to deal massive burst damage at once before being reanimated.The resurrection is a strong safety net but the long cooldown means opponents have time to punish Deathwalker when it is on cooldown. | Q11: Paid | R11: legendary_mech
A12: M011 | B12: Dreadnought | C12: Legendary | D12: Attacker | E12: A | F12: 227,300 | G12: 22 | H12: 32 | I12: 948 | J12: Wipe Out | K12: Rocket line attack (33m long, 19.8m wide) with EMP; kill resets cooldown. | L12: Ability Cooldown: 9 s | Wipe Out EMP Duration: 2 s | Wipe Out Damage: 74,319 | Wipe Out Area Size: 19.8 x 33 m² | M12: Huge burst damage in a short time. | N12: Short EMP duration. | O12: Wide AoE, EMP, high HP, and a kill-reset mechanic that lets it chain in team fights. One of the most impactful attackers in the game. | Q12: Paid | R12: legendary_mech
A13: M012 | B13: Eclipse | C13: Legendary | D13: Scout | E13: S | F13: 170,400 | G13: 28 | H13: 24 | I13: 948 | J13: Phase Cloak | K13: Phase Cloak — When active, increases Speed, ignores enemy targeting systems, and cannot be affected by Debuffs. | L13: Ability Cooldown: 10 s | Ability Duration: 8 s | M13: Full debuff immunity; stealth and speed boost; high HP and energy for a scout. | N13: Slightly slower than fastest scouts; no offensive output. | O13: Phase Cloak combines stealth, a speed boost, and complete debuff immunity for 8 seconds. One of the cleanest, most reliable scout abilities — no terrain or collision dependency. High HP and energy for a scout make it a consistent S-tier pick. | P13: 9375 | Q13: A-Coins | R13: legendary_mech
A14: M013 | B14: Gatecrasher | C14: Legendary | D14: Attacker | E14: A | F14: 221,600 | G14: 21 | H14: 32 | I14: 941 | J14: Ion Pod | K14: Ion Pod — Fires a Pod that sticks to surfaces or mechs; releases a damage-over-time beam through surfaces. | L14: Ability Cooldown: 10s | Ion Pod Range: 300m | Ion Beam Duration: 7s | Beam Blast Damage: 60,000 | Ion Beam Damage: 89,900 | Ion Beam Length: 16 m | Mech Blast Damage: 79,900 | Mech Blast Radius: 20 m | M14: Massive damage potential; versatile at long range; punishes enemies behind cover. | N14: Situational, doesn't deal a lot of damage. | O14: Enormous damage ceiling with the Ion Beam on surfaces, but the ability is highly situational — requires the right terrain and positioning to fully exploit | P14: 9375 | Q14: A-Coins | R14: legendary_mech
A15: M014 | B15: Guardian | C15: Rare | D15: Attacker | E15: C | F15: 140,700 | G15: 16 | H15: 32 | I15: 776 | J15: System Crash | K15: System Crash — Disables enemy Weapons and puts their Abilities on cooldown. | L15: Ability Cooldown: 15 s | System Crash Width: 60 m | System Crash Range: 30 m | M15: Shuts down enemy weapons and abilities; high energy capacity. | N15: Very slow; long cooldown. | O15: System Crash completely neutralizes any mech for its duration — no weapons, no abilities. Very slow speed is the main penalty since the ability is close ranged. | P15: 420 | Q15: A-Coins | R15: rare_mech
A16: M015 | B16: Hemlock | C16: Legendary | D16: Support | E16: A | F16: 204,500 | G16: 22 | H16: 24 | I16: 989 | J16: ECM Shot | K16: Pod that dazes enemy for 6s; if enemy takes damage, converts to 2s stun. | L16: Ability Cooldown: 16 s | Missed Ability Cooldown: 3s | Daze Delay: 1.5s | Daze Duration: 6s | EMP Duration: 2s | M16: Can almost permanently stun an enemy with maxed legendary implants. | N16: Very weak when ability is on cooldown. | O16: Good HP, medium energy, medium speed. Strong 1v1 or 2v2 ability at 50% cooldown. | P16: 937500 | Q16: Credits | R16: legendary_mech
A17: M016 | B17: Juggernaut | C17: Uncommon | D17: Tank | E17: C | F17: 152,200 | G17: 16 | H17: 24 | I17: 803 | J17: Personal Shield | K17: Personal Shield — Activates a personal shield that protects the Mech from damage. | L17: Ability Cooldown: 10 s | Ability Duration: 12s | Shield Durability: 31,600 | M17: Reliable damage buffer; decent cooldown. | N17: Slowest tank; lowest HP; no team utility; outclassed at higher rarities. | O17: The simplest tank ability — a plain personal shield with no team utility. Very low HP and the slowest speed of any tank makes it easy to kite. Outclassed by every other tank in the roster. | P17: 45 | Q17: A-Coins | R17: uncommon_mech
A18: M017 | B18: Killshot | C18: Epic B | D18: Scout | E18: B | F18: 119,500 | G18: 29 | H18: 24 | I18: 861 | J18: Melee Dash | K18: Dashes forward and deals impact damage. | L18: Ability Cooldown: 6 s | Ability Damage: 66,900 | Dash Distance: 40 m | Melee Dash Impact Radius: 12 m | M18: Strong melee burst. | N18: Fragile. | O18: A simple dash with no utility beyond the initial impact. Very fragile and the ability offers little beyond a single burst hit. Outclassed by every Legendary scout. | P18: 1865 | Q18: A-Coins | R18: epic_b_mech
A19: M018 | B19: Lacewing | C19: Legendary | D19: Scout | E19: S | F19: 198,900 | G19: 26 | H19: 24 | I19: 982 | J19: Mine Jump | K19: Double jump and places mines at jump location. | L19: Ability Cooldown: 7 s | Jump Distance: 10 m | Mine Damage: 38,000 | Mine Damage Radius: 12 m | Jump Charges: 2 | M19: Reaches high ground easily. | N19: None. | O19: Unique vertical mobility opens angles no other scout can access, and jump-placed mines punish predictable rotations. Niche but rewarding for map-aware players; outperformed by Nomad and Surge in direct combat. | P19: 9375 | Q19: A-Coins | R19: legendary_mech
A20: M019 | B20: Lancer | C20: Common | D20: Scout | E20: C | F20: 85,400 | G20: 25 | H20: 16 | I20: 814 | J20: Jump Jets | K20: Jump Jets — Activates a jump booster to reposition or avoid enemy fire. | L20: Ability Cooldown: 5 s | Jump Distance: 10 m | M20: Fast cooldown; useful for repositioning and high ground. | N20: Purely defensive; low energy cap; outclassed by other scouts. | O20: The simplest scout ability in the game — a repositioning jump with no offensive value. Lowest energy capacity of all scouts and fragile HP make it hard to justify over stronger options. | P20: 400 | Q20: Credits | R20: common_mech
A21: M020 | B21: MD | C21: Uncommon | H21: 16 | P21: 45 | Q21: A-Coins | R21: uncommon_mech
A22: M021 | B22: Mimicker | C22: Legendary | D22: Scout | E22: A | F22: 176,100 | G22: 27 | H22: 32 | I22: 887 | J22: Adaptation | K22: Scans enemy and adapts — Attackers: +50% dmg. Tanks: Gains shield. Scouts: Invisible+faster. Helpers: Heals on kill. | L22: Ability Cooldown: 9 s | Adaptation Range: 100 m | Shield Durability: 89,900 | Mech Healing Speed: 19,980 | Mech Bonus Damage: +30% | Ability Duration (Attacker): 8 s | Ability Duration (Tank): 8 s | Ability Duration (Scout): 8 s | Ability Duration (Support): 5 s | M22: Adaptable to any situation. | N22: Not dominant in any one role. | O22: Unique adaptability makes it versatile in any match, but being mediocre in every role rather than excellent in one holds it back. Best in unpredictable or solo-play scenarios. | P22: 937000 | Q22: Credits | R22: legendary_mech
A23: M022 | B23: Nomad | C23: Legendary | D23: Scout | E23: S | F23: 181,800 | G23: 29 | H23: 24 | I23: 962 | J23: Chain Dash | K23: Dash dealing massive damage + 60% damage reduction. | L23: Ability Cooldown: 8 s | Chain Dash Time: 3 s | Ability Damage: 70,200 | Dash Distance: 45 m | Damage Reduction From Dash: -60% | M23: Fast, agile, durable. | N23: None. | O23: The fastest scout with a dash that deals massive damage while taking only 40% incoming damage. Effectively near-immortal during the ability. The game itself lists no weaknesses — rightfully so. | P23: 9375 | Q23: A-Coins | R23: legendary_mech
A24: M023 | B24: Onyx | C24: Legendary | D24: Attacker | E24: B | F24: 198,900 | G24: 18 | H24: 32 | I24: 914 | J24: Quad Rocket | K24: Fires a rocket which deals light splash damage and heavy damage. | L24: Ability Cooldown: 10s | Damage Per Magazine: 69,833 | Magazine: 4 | Optimal Range: 0-100 m | Projectile Speed: 156 | Damage Radius: 7 m | M24: High burst damage and decent health. | N24: Low speed. | O24: Speed of 18 km/h is the joint slowest among Legendary attackers. The single-target rocket deals decent burst but not enough to compensate for being an easy slow-moving target. | Q24: Paid | R24: legendary_mech
A25: M024 | B25: Orion | C25: Epic B | D25: Support | E25: A | F25: 155,300 | G25: 23 | H25: 24 | I25: 895 | J25: Hunter's Mark | K25: Tracking flare applying Hunter's Mark (+150% dmg from weapons, brief Stasis). Mark spreads to a close enemy when targeted mech dies. | L25: Ability Cooldown: 12 s | Hunters Mark Damage: +150% | Shield Piercing Damage: +88% | Missed Mark Cooldown: 3 s | Mark Transfer Distance: 30 m | Mark Duration: 10 s | Mark Stasis Duration: 3 s | Shield Piercing Ratio: 66% | M25: Almost any weapon becomes strong due to the damage boost. | N25: Very ugly walking style (teammates suffer). | O25: Best Epic mech in the game. Ability makes weak weapons usable. Mid speed, mid energy, slightly low-mid HP. | P25: 1865 | Q25: A-Coins | R25: epic_b_mech
A26: M025 | B26: Outlaw | C26: Legendary | D26: Attacker | E26: S | F26: 213,100 | G26: 20 | H26: 32 | I26: 931 | J26: Foul Play | K26: Pod that reloads/resets a single opponent's mech and weapons. | L26: Ability Cooldown: 15 s | Foul Play Range: 100 m | Foul Play Radius: 5 m | M26: Usually disables an opponent for a short time. | N26: Not effective against short-reload mechs/weapons; useless vs invisible mechs. | O26: Medium speed, good ability, good HP and energy capacity. | P26: 9375 | Q26: A-Coins | R26: legendary_mech
A27: M026 | B27: Panther | C27: Epic C | D27: Attacker | E27: A | F27: 119,500 | G27: 20 | H27: 32 | I27: 793 | J27: Stasis Barrier | K27: Places an immortal Barrier that inflicts Stasis on contact. | L27: Ability Cooldown: 10 s | Ability Duration: 10 s | Stasis Effect Time: 4 s | Stasis Barrier Height: 6 m | M27: Excellent protection and high energy capacity. | N27: Very fragile without the Barrier. | O27: The immortal Barrier with Stasis is powerful zone control, but Panther is very fragile without it. Strong in skilled hands but punished hard on cooldown. | P27: 2425 | Q27: A-Coins | R27: epic_c_mech
A28: M027 | B28: Paragon | C28: Common | D28: Attacker | E28: D | F28: 85,400 | G28: 18 | H28: 32 | I28: 678 | J28: Boost | K28: Makes the mech move faster for a limited amount of time | L28: Ability Cooldown: 9 s | Ability Duration: 6 s | M28: High energy capacity, decent walk speed on ability | N28: Horrible health, low speed when ability is not active | O28: Very low health and speed, paired with a weak ability. The only plus side is the energy capacity and cheapness to upgrade it. | Q28: free | R28: common_mech
A29: M028 | B29: Parasite | C29: Legendary | D29: Tank | E29: S | F29: 261,300 | G29: 20 | H29: 24 | I29: 1,029 | J29: Redirection | K29: Links onto an enemy; takes only 10% damage while transferring 35% to the linked mech. | L29: Ability Cooldown: 11 s | Ability Duration: 12s | Ability Activation Range: 85 m | Redirection Range: 110 m | Damage Received: 10% | Damage Redirected: 35% | M29: Nearly immortal while linked. | N29: Relatively slow. | O29: Huge HP, almost immortal when linked, medium speed. | Q29: Paid | R29: legendary_mech
A30: M029 | B30: Puma | C30: Uncommon | D30: Attacker | E30: D | F30: 67,600 | G30: 20 | H30: 32 | I30: 703 | J30: Shield Wall | K30: Deploys a static Shield Wall that blocks enemy projectiles until it expires or is destroyed. | L30: Ability Cooldown: 10 s | Ability Duration: 10 s | Shield Wall Durability: 67,800 | Shield Wall Height: 6 m | M30: Shield Wall blocks incoming projectiles; decent energy capacity for an Uncommon mech. | N30: Lowest HP of any attacker; static ability is easily avoided by flanking or vertical movement. | O30: One of the original starter mechs. Extremely low HP and power compared to every other attacker. The Shield Wall is defensive but static — easily flanked and outscaled. | P30: 45 | Q30: A-Coins | R30: uncommon_mech
A31: M030 | B31: Redeemer | C31: Epic B | D31: Scout | E31: B | F31: 167,300 | G31: 29 | H31: 24 | I31: 967 | J31: Backtrack | K31: Rewinds 10 seconds and becomes immortal during rewind. | L31: Ability Cooldown: 14 s | Backtrack Timer: 10 | Debuffs Removed: All Debuffs (19) | M31: Extremely agile and fast. | N31: Fragile, long ability cooldown. | O31: Very fast, unique ability. Mid HP, decent energy, high ability cooldown. | P31: 1865 | Q31: A-Coins | R31: epic_b_mech
A32: M031 | B32: Redox | C32: Legendary | D32: Attacker | E32: A | F32: 227,300 | G32: 22 | H32: 32 | I32: 948 | J32: Caustic Blast | K32: Creates a 30m radius caustic blast — stasis + damage over time. Grants a Personal Shield and a Speed Boost for the ability duration. | L32: Ability Cooldown: 8 s | Ability Duration: 6 s | Ability Damage: 79,600 | Caustic Blast Radius: 30 m | Caustic Blast Stasis Time: 6 s | Shield Durability: 31,600 | Speed Boost: +50% | M32: High HP and speed; personal shield extends survivability; 30m AoE stasis slows multiple mechs; strong ability damage; high energy capacity. | N32: Damage over time rather than burst; personal shield is modest; speed boost only active during ability. | O32: Significant buffs bring Redox to Dreadnought-level HP and speed, while adding a personal shield and speed boost during the ability. The 30m AoE stasis+DoT is effective in group fights. Stays out of S because DoT is less impactful than burst damage and the personal shield is modest. | P32: 9375 | Q32: A-Coins | R32: legendary_mech
A33: M032 | B33: Salvor | C33: Legendary | D33: Support | E33: A | F33: 227,300 | G33: 24 | H33: 32 | I33: 948 | J33: Regen Shot | K33: Regen Shot — Fires up to 3 homing healing projectiles at allies. Also heals Salvor. Cannot heal shields or through walls. | L33: Ability Cooldown: 12 s | Regen Shot Range: 100 m | HP Healed (Allies): 60,130 | HP Healed (Self): 30,230 | Regen Shot Charges: 3 | M33: One of two healing mechs; high-burst healing; also heals self; highest power of any support. | N33: Cannot heal shields; requires line of sight. | O33: One of two dedicated healers in the game alongside M.D. Three charges provide up to 180k HP restoration per cycle, with self-healing on top. Significantly outperforms M.D. in burst healing, range (100m vs 10m), and energy capacity. The inability to heal shields or through obstacles is the main limitation. | Q33: Paid | R33: legendary_mech
A34: M033 | B34: Scorpius | C34: Legendary | D34: Attacker | E34: B | F34: 176,100 | G34: 21 | H34: 32 | I34: 887 | J34: Javelin Array | K34: Fires guided shoulder-mounted rockets similar to Javelin racks. | L34: Ability Cooldown: 7 s | Damage Per Magazine: 41,076 | Magazine: 2 | Optimal Range: 16-75 m | Projectile Speed: 20 | Damage Radius: 3 m | Lock Time: 0.7 s | M34: Can hit enemies without direct line of sight; unpredictable. | N34: Mediocre speed, low-damage ability. | O34: Weak ability, good energy capacity, mildly decent HP. | P34: 9375 | Q34: A-Coins | R34: legendary_mech
A35: M034 | B35: Seeker | C35: Legendary | D35: Attacker | E35: S | F35: 193,200 | G35: 22 | H35: 24 | I35: 975 | J35: Warp | K35: Warp — Teleports to an enemy, activates a shield and deals bonus damage on arrival, then returns. | L35: Ability Cooldown: 8 s | Ability Duration: 7 s | Shield Durability: 34,200 | Warp Range: 100 m | Warp Duration: 1s | Warp Bonus Damage: +30% | M35: Invincible during warp; shield and bonus damage on arrival. | N35: Short active window; returns to origin; low energy capacity. | O35: Invincible during warp, shielded on arrival, and boosted damage creates a guaranteed aggressive burst window. Reliable and consistent against campers | P35: 9375 | Q35: A-Coins | R35: legendary_mech
A36: M035 | B36: Sentinel | C36: Epic A | D36: Tank | E36: B | F36: 203,100 | G36: 19 | H36: 24 | I36: 941 | J36: Tall Shield | K36: Tall Shield — Deploys a vertical barrier blocking arcing projectiles. Regenerates faster as Sentinel takes damage at max level. | L36: Ability Cooldown: 12 s | Shield Durability: 57,400 | Ability Cooldown (HP%): 100% - 12s<br>80% - 10s<br>60% - 8s<br>40% - 6s<br>20% - 4s | M36: Blocks arcing projectiles; shield regenerates faster under pressure. | N36: Niche against certain weapons; long cooldown; lower durability than Blockhorn. | O36: Uniquely counters arcing and overhead fire that most shields cannot block. The HP-scaling cooldown reduction makes it more reactive under pressure. Solid HP for an Epic but the niche defensive profile keeps it out of A tier. | P36: 130600 | Q36: Credits | R36: epic_a_mech
A37: M036 | B37: Shadow | C37: Rare | D37: Scout | E37: C | F37: 80,400 | G37: 29 | H37: 16 | I37: 869 | J37: Stealth | K37: Stealth — While active, the Mech moves faster and is ignored by enemy targeting systems. | L37: Ability Cooldown: 8 s | Ability Duration: 12 s | M37: Long stealth duration; speed boost while in stealth. | N37: Low energy capacity; low HP; no offensive bonus. | O37: A long 12s stealth window with a speed boost is genuinely useful for flanking and repositioning. Held back by the lowest energy cap and very low HP. | P37: 420 | Q37: A-Coins | R37: rare_mech
A38: M037 | B38: Silverthorn | C38: Legendary | D38: Attacker | E38: D | F38: 221,600 | G38: 23 | H38: 32 | I38: 941 | J38: Blade Burst | K38: Shoots 5 blades which slow down targets and deal AoE damage. | L38: Ability Cooldown: 7 s | Ability Duration: 3.5 s | Ability Cooldown (Miss): 4 s | Blade Burst DMG Radius: 100 m | Blade Count: 5 | Enemy Speed Reduction: 40 % | Blade Hit Damage: 8,784 | Blade Splash Damage: 2,000 | Extra Damage %: 50% | Maximum Extra Damage: 60,000 | M38: Good control against multiple mechs; fastest attacker in the game. | N38: Low blade damage | O38: Very bad ability, low max damage makes it even worse than mechs like Stalker | P38: 9375 | Q38: A-Coins | R38: legendary_mech
A39: M038 | B39: Slingshot | C39: Uncommon | D39: Scout | E39: C | F39: 67,600 | G39: 29 | H39: 24 | I39: 771 | J39: Force Dash | K39: Force Dash — Launches the Mech forward. Colliding with any object creates an AOE Smash dealing damage to nearby enemies. | L39: Ability Cooldown: 6s | Ability Damage: 22,600 | Dash Distance: 40 m | AOE Smash Impact Radius: 12 m | M39: Maximum speed; AoE dash can hit multiple enemies. | N39: Lowest HP of any scout; ability requires collision to trigger. | O39: The lowest HP of any scout — even below Puma. The Force Dash AoE is fun and can deal decent damage, but Slingshot dies so fast that landing it consistently is very hard. | P39: 45 | Q39: A-Coins | R39: uncommon_mech
A40: M039 | B40: Solis | C40: Legendary | D40: Support | E40: A | F40: 170,400 | G40: 20 | H40: 32 | I40: 880 | J40: Optic Override | K40: Throws 2 orbs that blind enemy mechs in a small radius for 1.5s and grants a +80% Speed Boost for 3s (does NOT work against bots). Cooldown: 12s. | L40: Ability Cooldown: 12 s | Optic Override Radius: 15 m | Blind Effect Duration: 1.5 s | Orb Count: 2 | Speed Boost: +80% | M40: +80% speed boost briefly improves mobility and escape; ability still annoys human opponents. | N40: 1.5s blind is very short; 12s cooldown means long windows of no utility; does not affect bots; below-average base speed. | O40: An effective mech when dealing with other players, also makes ambushes easier. Relatively fragile but has high energy capacity. | P40: 937500 | Q40: Credits | R40: legendary_mech
...

Sheet Mech Upgrade Costs
A1: Rarity Key | B1: Star | C1: Level | D1: Credits | E1: A-Coins | F1: Blueprints | G1: Step
A2: common_mech | B2: 1 | C2: 1 | D2: 75 | E2: 0 | F2: 1 | G2: =(B2-1)*7+C2
A3: uncommon_mech | B3: 1 | C3: 1 | D3: 0 | E3: 0 | F3: 0 | G3: =(B3-1)*7+C3
A4: rare_mech | B4: 1 | C4: 1 | D4: 0 | E4: 0 | F4: 0 | G4: =(B4-1)*7+C4
A5: epic_a_mech | B5: 1 | C5: 1 | D5: 0 | E5: 0 | F5: 0 | G5: =(B5-1)*7+C5
A6: epic_b_mech | B6: 1 | C6: 1 | D6: 0 | E6: 0 | F6: 0 | G6: =(B6-1)*7+C6
A7: epic_c_mech | B7: 1 | C7: 1 | D7: 0 | E7: 0 | F7: 0 | G7: =(B7-1)*7+C7
A8: legendary_mech | B8: 1 | C8: 1 | D8: 825 | E8: 0 | F8: 1 | G8: =(B8-1)*7+C8
A9: common_mech | B9: 1 | C9: 2 | D9: 125 | E9: 0 | F9: 1 | G9: =(B9-1)*7+C9
A10: uncommon_mech | B10: 1 | C10: 2 | D10: 0 | E10: 0 | F10: 0 | G10: =(B10-1)*7+C10
A11: rare_mech | B11: 1 | C11: 2 | D11: 0 | E11: 0 | F11: 0 | G11: =(B11-1)*7+C11
A12: epic_a_mech | B12: 1 | C12: 2 | D12: 0 | E12: 0 | F12: 0 | G12: =(B12-1)*7+C12
A13: epic_b_mech | B13: 1 | C13: 2 | D13: 0 | E13: 0 | F13: 0 | G13: =(B13-1)*7+C13
... A295: legendary_mech | B295: 6 | C295: 7 | D295: 0 | E295: 0 | F295: 0 | G295: =(B295-1)*7+C295

Sheet Weapons
A1: Weapon ID | B1: Name | C1: Base Name | D1: Rarity | E1: Category | F1: Tier | G1: Energy | H1: Fire Rate | I1: Magazine | J1: Reload Speed | K1: Optimal Range | L1: Max Range | M1: Perk | N1: Perk Description | O1: Weapon Effect | P1: Proc Damage | Q1: Proc Interval | R1: Charge Offset | S1: Base DPM | T1: DMG/Energy | U1: Range Rating | V1: Accuracy Rating | W1: Perk Rating | X1: Efficiency Rating | Y1: DMG/Energy Rating | Z1: Strengths | AA1: Weaknesses | AB1: Reasoning | AC1: Unlock Cost | AD1: Unlock Currency | AE1: Rarity Key
A2: W001 | B2: Arc Torrent 6 | C2: Arc Torrent | D2: Epic B | E2: Close Quarters | F2: C | G2: 6 | H2: 124 rpm | I2: 25 | J2: 15s | K2: 0–30m | L2: 30m | M2: High Voltage | N2: Applies a Shock Effect that destabilizes the crosshair of the target. | T2: ~259 | U2: 5 | V2: 3 | W2: 4 | X2: 1 | Y2: 1 | Z2: High Voltage Shock destabilizes aim rapidly. | AA2: Worst dmgPerEnergy of all CQ weapons; one of the worst reloads in the game; raw damage relies entirely on Shock utility. | AB2: CQ utility outlier — Shocks enemies from outside their comfortable fight-back range. One of the worst reloads in the game. Strong in coordinated play; weak solo. | AC2: 77250 | AD2: Credits | AE2: epic_b_weapon_6
A3: W002 | B3: Arc Torrent 10 | C3: Arc Torrent | D3: Epic B | E3: Close Quarters | F3: C | G3: 10 | H3: 124 rpm | I3: 25 | J3: 15s | K3: 0–30m | L3: 30m | M3: High Voltage | N3: Applies a Shock Effect that destabilizes the crosshair of the target. | T3: ~259 | U3: 5 | V3: 3 | W3: 4 | X3: 1 | Y3: 1 | Z3: High Voltage Shock destabilizes aim rapidly. | AA3: Worst dmgPerEnergy of all CQ weapons; one of the worst reloads in the game; raw damage relies entirely on Shock utility. | AB3: CQ utility outlier — Shocks enemies from outside their comfortable fight-back range. One of the worst reloads in the game. Strong in coordinated play; weak solo. | AC3: 870 | AD3: A-Coins | AE3: epic_b_weapon_10
A4: W003 | B4: Arc Torrent 12 | C4: Arc Torrent | D4: Epic B | E4: Close Quarters | F4: C | G4: 12 | H4: 124 rpm | I4: 25 | J4: 15s | K4: 0–30m | L4: 30m | M4: High Voltage | N4: Applies a Shock Effect that destabilizes the crosshair of the target. | T4: ~259 | U4: 5 | V4: 3 | W4: 4 | X4: 1 | Y4: 1 | Z4: High Voltage Shock destabilizes aim rapidly. | AA4: Worst dmgPerEnergy of all CQ weapons; one of the worst reloads in the game; raw damage relies entirely on Shock utility. | AB4: CQ utility outlier — Shocks enemies from outside their comfortable fight-back range. One of the worst reloads in the game. Strong in coordinated play; weak solo. | AC4: 910 | AD4: A-Coins | AE4: epic_b_weapon_12
A5: W004 | B5: Autocannon 2 | C5: Autocannon | D5: Common | E5: Assault | F5: D | G5: 2 | H5: 606 rpm | I5: 90 | J5: 6.6s | K5: 0–45m | L5: 135m | M5: Adaptable | N5: Effective at most ranges and has high ammunition. | T5: 374 | U5: 3 | V5: 4 | W5: 2 | X5: 5 | Y5: 1 | Z5: Extremely energy-efficient; high ammo count; consistent sustained fire at all engagement ranges. | AA5: Low damage ceiling; outscaled quickly by Rare and above; Common rarity limits maximum potential. | AB5: The Autocannon is the reliable starter weapon for tight-energy builds. Adaptable keeps it useful at various ranges but raw damage falls off hard. Worth using as a 2-energy filler — nothing more. | AC5: 50 | AD5: Credits | AE5: common_weapon_2
A6: W005 | B6: Autocannon 4 | C6: Autocannon | D6: Common | E6: Assault | F6: D | G6: 4 | H6: 606 rpm | I6: 90 | J6: 6.6s | K6: 0–45m | L6: 135m | M6: Adaptable | N6: Effective at most ranges and has high ammunition. | T6: 374 | U6: 3 | V6: 4 | W6: 2 | X6: 5 | Y6: 1 | Z6: Extremely energy-efficient; high ammo count; consistent sustained fire at all engagement ranges. | AA6: Low damage ceiling; outscaled quickly by Rare and above; Common rarity limits maximum potential. | AB6: The Autocannon is the reliable starter weapon for tight-energy builds. Adaptable keeps it useful at various ranges but raw damage falls off hard. Worth using as a 2-energy filler — nothing more. | AD6: free | AE6: common_weapon_4
A7: W006 | B7: Berserker 6 | C7: Berserker | D7: Legendary | E7: Assault | F7: B | G7: 6 | H7: 608 rpm | I7: 80 | J7: 8s | K7: 0–60m | L7: 90m | M7: Pulverize | N7: Firing increases bullet dispersion. However, each bullet's Crit Chance steadily increases until the end of the Magazine, up to 100%. | O7: Ramps to 2x crit | T7: ~1,044 | U7: 3 | V7: 2 | W7: 3 | X7: 3 | Y7: 3 | Z7: 100% crit chance at end of magazine is enormous; large 80-round mag gives long crit ramp window; 30% double damage chance stacks on top. | AA7: Bullet dispersion grows as crit chance climbs — late-mag accuracy is poor at range; longest reload of any assault weapon. | AB7: High-risk, high-reward. Crit ramp to 100% is devastating on paper but spread grows simultaneously, undermining accuracy at distance. Best in close-range brawls where spread is irrelevant. The long reload demands you finish fights fast. | AC7: 600000 | AD7: Credits | AE7: legendary_weapon_6
A8: W007 | B8: Berserker 8 | C8: Berserker | D8: Legendary | E8: Assault | F8: B | G8: 8 | H8: 608 rpm | I8: 80 | J8: 8s | K8: 0–60m | L8: 90m | M8: Pulverize | N8: Firing increases bullet dispersion. However, each bullet's Crit Chance steadily increases until the end of the Magazine, up to 100%. | O8: Ramps to 2x crit | T8: ~1,044 | U8: 3 | V8: 2 | W8: 3 | X8: 3 | Y8: 3 | Z8: 100% crit chance at end of magazine is enormous; large 80-round mag gives long crit ramp window; 30% double damage chance stacks on top. | AA8: Bullet dispersion grows as crit chance climbs — late-mag accuracy is poor at range; longest reload of any assault weapon. | AB8: High-risk, high-reward. Crit ramp to 100% is devastating on paper but spread grows simultaneously, undermining accuracy at distance. Best in close-range brawls where spread is irrelevant. The long reload demands you finish fights fast. | AC8: 8275 | AD8: A-Coins | AE8: legendary_weapon_8
A9: W008 | B9: Berserker 10 | C9: Berserker | D9: Legendary | E9: Assault | F9: B | G9: 10 | H9: 608 rpm | I9: 80 | J9: 8s | K9: 0–60m | L9: 90m | M9: Pulverize | N9: Firing increases bullet dispersion. However, each bullet's Crit Chance steadily increases until the end of the Magazine, up to 100%. | O9: Ramps to 2x crit | T9: ~1,044 | U9: 3 | V9: 2 | W9: 3 | X9: 3 | Y9: 3 | Z9: 100% crit chance at end of magazine is enormous; large 80-round mag gives long crit ramp window; 30% double damage chance stacks on top. | AA9: Bullet dispersion grows as crit chance climbs — late-mag accuracy is poor at range; longest reload of any assault weapon. | AB9: High-risk, high-reward. Crit ramp to 100% is devastating on paper but spread grows simultaneously, undermining accuracy at distance. Best in close-range brawls where spread is irrelevant. The long reload demands you finish fights fast. | AC9: 712500 | AD9: Credits | AE9: legendary_weapon_10
A10: W009 | B10: Berserker 12 | C10: Berserker | D10: Legendary | E10: Assault | F10: B | G10: 12 | H10: 608 rpm | I10: 80 | J10: 8s | K10: 0–60m | L10: 90m | M10: Pulverize | N10: Firing increases bullet dispersion. However, each bullet's Crit Chance steadily increases until the end of the Magazine, up to 100%. | O10: Ramps to 2x crit | T10: ~1,044 | U10: 3 | V10: 2 | W10: 3 | X10: 3 | Y10: 3 | Z10: 100% crit chance at end of magazine is enormous; large 80-round mag gives long crit ramp window; 30% double damage chance stacks on top. | AA10: Bullet dispersion grows as crit chance climbs — late-mag accuracy is poor at range; longest reload of any assault weapon. | AB10: High-risk, high-reward. Crit ramp to 100% is devastating on paper but spread grows simultaneously, undermining accuracy at distance. Best in close-range brawls where spread is irrelevant. The long reload demands you finish fights fast. | AC10: 7500 | AD10: A-Coins | AE10: legendary_weapon_12
A11: W010 | B11: Berserker 16 | C11: Berserker | D11: Legendary | E11: Assault | F11: B | G11: 16 | H11: 608 rpm | I11: 80 | J11: 8s | K11: 0–60m | L11: 90m | M11: Pulverize | N11: Firing increases bullet dispersion. However, each bullet's Crit Chance steadily increases until the end of the Magazine, up to 100%. | O11: Ramps to 2x crit | T11: ~1,044 | U11: 3 | V11: 2 | W11: 3 | X11: 3 | Y11: 3 | Z11: 100% crit chance at end of magazine is enormous; large 80-round mag gives long crit ramp window; 30% double damage chance stacks on top. | AA11: Bullet dispersion grows as crit chance climbs — late-mag accuracy is poor at range; longest reload of any assault weapon. | AB11: High-risk, high-reward. Crit ramp to 100% is devastating on paper but spread grows simultaneously, undermining accuracy at distance. Best in close-range brawls where spread is irrelevant. The long reload demands you finish fights fast. | AC11: 827500 | AD11: Credits | AE11: legendary_weapon_16
A12: W011 | B12: Blast RPG 6 | C12: Blast RPG | D12: Legendary | E12: Missile | F12: B | G12: 6 | H12: 170 rpm | I12: 10 | J12: 8s | K12: 0–120m | L12: 120m | M12: Power Play | N12: Missiles deal damage in a large radius around their impact point. Missiles will be attracted towards nearby enemy Mechs on their flight path. | T12: ~692 | U12: 3 | W12: 3 | Y12: 3 | Z12: Large blast radius absorbs near-misses; Power Play auto-attraction reduces aim demand in messy engagements; large 10-shot magazine; 120m range; now competitive DPS/Energy. | AA12: Power Play homing is unreliable against fast or evasive mechs; no CC or utility. | AB12: The damage is quite weak, the homing also makes back hits more difficult, also making the radius less useful. The large blast radius and Power Play attraction remain its identity — the most forgiving Legendary missile now also hits hard enough to matter. | AD12: Paid | AE12: legendary_weapon_6
A13: W012 | B13: Blast RPG 8 | C13: Blast RPG | D13: Legendary | E13: Missile | F13: B | G13: 8 | H13: 170 rpm | I13: 10 | J13: 8s | K13: 0–120m | L13: 120m | M13: Power Play | N13: Missiles deal damage in a large radius around their impact point. Missiles will be attracted towards nearby enemy Mechs on their flight path. | T13: ~692 | U13: 3 | W13: 3 | Y13: 3 | Z13: Large blast radius absorbs near-misses; Power Play auto-attraction reduces aim demand in messy engagements; large 10-shot magazine; 120m range; now competitive DPS/Energy. | AA13: Power Play homing is unreliable against fast or evasive mechs; no CC or utility. | AB13: The damage is quite weak, the homing also makes back hits more difficult, also making the radius less useful. The large blast radius and Power Play attraction remain its identity — the most forgiving Legendary missile now also hits hard enough to matter. | AD13: Paid | AE13: legendary_weapon_8
A14: W013 | B14: Blast RPG 10 | C14: Blast RPG | D14: Legendary | E14: Missile | F14: B | G14: 10 | H14: 170 rpm | I14: 10 | J14: 8s | K14: 0–120m | L14: 120m | M14: Power Play | N14: Missiles deal damage in a large radius around their impact point. Missiles will be attracted towards nearby enemy Mechs on their flight path. | T14: ~692 | U14: 3 | W14: 3 | Y14: 3 | Z14: Large blast radius absorbs near-misses; Power Play auto-attraction reduces aim demand in messy engagements; large 10-shot magazine; 120m range; now competitive DPS/Energy. | AA14: Power Play homing is unreliable against fast or evasive mechs; no CC or utility. | AB14: The damage is quite weak, the homing also makes back hits more difficult, also making the radius less useful. The large blast radius and Power Play attraction remain its identity — the most forgiving Legendary missile now also hits hard enough to matter. | AD14: Paid | AE14: legendary_weapon_10
A15: W014 | B15: Blast RPG 12 | C15: Blast RPG | D15: Legendary | E15: Missile | F15: B | G15: 12 | H15: 170 rpm | I15: 10 | J15: 8s | K15: 0–120m | L15: 120m | M15: Power Play | N15: Missiles deal damage in a large radius around their impact point. Missiles will be attracted towards nearby enemy Mechs on their flight path. | T15: ~692 | U15: 3 | W15: 3 | Y15: 3 | Z15: Large blast radius absorbs near-misses; Power Play auto-attraction reduces aim demand in messy engagements; large 10-shot magazine; 120m range; now competitive DPS/Energy. | AA15: Power Play homing is unreliable against fast or evasive mechs; no CC or utility. | AB15: The damage is quite weak, the homing also makes back hits more difficult, also making the radius less useful. The large blast radius and Power Play attraction remain its identity — the most forgiving Legendary missile now also hits hard enough to matter. | AD15: Paid | AE15: legendary_weapon_12
A16: W015 | B16: Blast RPG 16 | C16: Blast RPG | D16: Legendary | E16: Missile | F16: B | G16: 16 | H16: 170 rpm | I16: 10 | J16: 8s | K16: 0–120m | L16: 120m | M16: Power Play | N16: Missiles deal damage in a large radius around their impact point. Missiles will be attracted towards nearby enemy Mechs on their flight path. | T16: ~692 | U16: 3 | W16: 3 | Y16: 3 | Z16: Large blast radius absorbs near-misses; Power Play auto-attraction reduces aim demand in messy engagements; large 10-shot magazine; 120m range; now competitive DPS/Energy. | AA16: Power Play homing is unreliable against fast or evasive mechs; no CC or utility. | AB16: The damage is quite weak, the homing also makes back hits more difficult, also making the radius less useful. The large blast radius and Power Play attraction remain its identity — the most forgiving Legendary missile now also hits hard enough to matter. | AD16: Paid | AE16: legendary_weapon_16
A17: W016 | B17: Bouncecritter 6 | C17: Bouncecritter | D17: Legendary | G17: 6 | AD17: Paid | AE17: legendary_weapon_6
A18: W017 | B18: Bouncecritter 8 | C18: Bouncecritter | D18: Legendary | G18: 8 | AD18: Paid | AE18: legendary_weapon_8
A19: W018 | B19: Bouncecritter 10 | C19: Bouncecritter | D19: Legendary | G19: 10 | AD19: Paid | AE19: legendary_weapon_10
A20: W019 | B20: Bouncecritter 12 | C20: Bouncecritter | D20: Legendary | G20: 12 | AD20: Paid | AE20: legendary_weapon_12
A21: W020 | B21: Bouncecritter 16 | C21: Bouncecritter | D21: Legendary | G21: 16 | AD21: Paid | AE21: legendary_weapon_16
A22: W021 | B22: Burrow beam 6 | C22: Burrow beam | D22: Legendary | E22: Beam | F22: S | G22: 6 | H22: 154 rpm | I22: 20 | J22: 4.5s | K22: 0–80m | L22: 80m | M22: Piercing Laser | N22: Fires a straight, continuous beam which passes through Mechs. Has a single charge in its Magazine, which reloads when empty. The beam cannot pass through objects, walls or any environmental obstructions. | R22: 1 | T22: ~713 | U22: 3 | W22: 5 | Y22: 3 | Z22: Piercing Laser hits every mech in a line for full damage — real output multiplies in group fights; +6.82% damage per shot partially offsets reload nerf. | AA22: Beam cannot penetrate walls or objects; 80m max range is the second shortest of all Legendary beams; 70% of damage dealt to Shields rather than HP — less effective against shield-depleted targets; longer 13.3s cycle (7.8s fire + 4.5s reload + 1s delay). | AB22: Heavy Damage and a moderate range. Reload is mid but with the correct implant setups its one of the best weapons in the game. | AD22: Paid | AE22: legendary_weapon_6
A23: W022 | B23: Burrow beam 8 | C23: Burrow beam | D23: Legendary | E23: Beam | F23: S | G23: 8 | H23: 154 rpm | I23: 20 | J23: 4.5s | K23: 0–80m | L23: 80m | M23: Piercing Laser | N23: Fires a straight, continuous beam which passes through Mechs. Has a single charge in its Magazine, which reloads when empty. The beam cannot pass through objects, walls or any environmental obstructions. | R23: 1 | T23: ~713 | U23: 3 | W23: 5 | Y23: 3 | Z23: Piercing Laser hits every mech in a line for full damage — real output multiplies in group fights; +6.82% damage per shot partially offsets reload nerf. | AA23: Beam cannot penetrate walls or objects; 80m max range is the second shortest of all Legendary beams; 70% of damage dealt to Shields rather than HP — less effective against shield-depleted targets; longer 13.3s cycle (7.8s fire + 4.5s reload + 1s delay). | AB23: Heavy Damage and a moderate range. Reload is mid but with the correct implant setups its one of the best weapons in the game. | AD23: Paid | AE23: legendary_weapon_8
A24: W023 | B24: Burrow beam 10 | C24: Burrow beam | D24: Legendary | E24: Beam | F24: S | G24: 10 | H24: 154 rpm | I24: 20 | J24: 4.5s | K24: 0–80m | L24: 80m | M24: Piercing Laser | N24: Fires a straight, continuous beam which passes through Mechs. Has a single charge in its Magazine, which reloads when empty. The beam cannot pass through objects, walls or any environmental obstructions. | R24: 1 | T24: ~713 | U24: 3 | W24: 5 | Y24: 3 | Z24: Piercing Laser hits every mech in a line for full damage — real output multiplies in group fights; +6.82% damage per shot partially offsets reload nerf. | AA24: Beam cannot penetrate walls or objects; 80m max range is the second shortest of all Legendary beams; 70% of damage dealt to Shields rather than HP — less effective against shield-depleted targets; longer 13.3s cycle (7.8s fire + 4.5s reload + 1s delay). | AB24: Heavy Damage and a moderate range. Reload is mid but with the correct implant setups its one of the best weapons in the game. | AD24: Paid | AE24: legendary_weapon_10
A25: W024 | B25: Burrow beam 12 | C25: Burrow beam | D25: Legendary | E25: Beam | F25: S | G25: 12 | H25: 154 rpm | I25: 20 | J25: 4.5s | K25: 0–80m | L25: 80m | M25: Piercing Laser | N25: Fires a straight, continuous beam which passes through Mechs. Has a single charge in its Magazine, which reloads when empty. The beam cannot pass through objects, walls or any environmental obstructions. | R25: 1 | T25: ~713 | U25: 3 | W25: 5 | Y25: 3 | Z25: Piercing Laser hits every mech in a line for full damage — real output multiplies in group fights; +6.82% damage per shot partially offsets reload nerf. | AA25: Beam cannot penetrate walls or objects; 80m max range is the second shortest of all Legendary beams; 70% of damage dealt to Shields rather than HP — less effective against shield-depleted targets; longer 13.3s cycle (7.8s fire + 4.5s reload + 1s delay). | AB25: Heavy Damage and a moderate range. Reload is mid but with the correct implant setups its one of the best weapons in the game. | AD25: Paid | AE25: legendary_weapon_12
A26: W025 | B26: Burrow beam 16 | C26: Burrow beam | D26: Legendary | E26: Beam | F26: S | G26: 16 | H26: 154 rpm | I26: 20 | J26: 4.5s | K26: 0–80m | L26: 80m | M26: Piercing Laser | N26: Fires a straight, continuous beam which passes through Mechs. Has a single charge in its Magazine, which reloads when empty. The beam cannot pass through objects, walls or any environmental obstructions. | R26: 1 | T26: ~713 | U26: 3 | W26: 5 | Y26: 3 | Z26: Piercing Laser hits every mech in a line for full damage — real output multiplies in group fights; +6.82% damage per shot partially offsets reload nerf. | AA26: Beam cannot penetrate walls or objects; 80m max range is the second shortest of all Legendary beams; 70% of damage dealt to Shields rather than HP — less effective against shield-depleted targets; longer 13.3s cycle (7.8s fire + 4.5s reload + 1s delay). | AB26: Heavy Damage and a moderate range. Reload is mid but with the correct implant setups its one of the best weapons in the game. | AD26: Paid | AE26: legendary_weapon_16
A27: W026 | B27: Carbine 8 | C27: Carbine | D27: Legendary | E27: Assault | F27: C | G27: 8 | H27: 384 rpm | I27: 50 | J27: 6.2s | K27: 0–30m | L27: 120m | M27: Burst Fire | N27: Fires short bursts of high-damage, high-velocity rounds. | T27: ~636 | U27: 3 | V27: 4 | W27: 3 | X27: 3 | Y27: 2 | Z27: High-velocity projectiles (160 speed); 120m max range offers flexible positioning; burst pattern rewards precise aim. | AA27: Only 30m optimal range — extremely tight engagement window; below-average fire rate; only available at energy 8+. | AB27: The Carbine is a specialist weapon for aggressive mechs that close distance fast. Lacks heavily in damage. | AC27: 8275 | AD27: A-Coins | AE27: legendary_weapon_8
A28: W027 | B28: Carbine 10 | C28: Carbine | D28: Legendary | E28: Assault | F28: C | G28: 10 | H28: 384 rpm | I28: 50 | J28: 6.2s | K28: 0–30m | L28: 120m | M28: Burst Fire | N28: Fires short bursts of high-damage, high-velocity rounds. | T28: ~636 | U28: 3 | V28: 4 | W28: 3 | X28: 3 | Y28: 2 | Z28: High-velocity projectiles (160 speed); 120m max range offers flexible positioning; burst pattern rewards precise aim. | AA28: Only 30m optimal range — extremely tight engagement window; below-average fire rate; only available at energy 8+. | AB28: The Carbine is a specialist weapon for aggressive mechs that close distance fast. Lacks heavily in damage. | AC28: 7125 | AD28: A-Coins | AE28: legendary_weapon_10
A29: W028 | B29: Carbine 12 | C29: Carbine | D29: Legendary | E29: Assault | F29: C | G29: 12 | H29: 384 rpm | I29: 50 | J29: 6.2s | K29: 0–30m | L29: 120m | M29: Burst Fire | N29: Fires short bursts of high-damage, high-velocity rounds. | T29: ~636 | U29: 3 | V29: 4 | W29: 3 | X29: 3 | Y29: 2 | Z29: High-velocity projectiles (160 speed); 120m max range offers flexible positioning; burst pattern rewards precise aim. | AA29: Only 30m optimal range — extremely tight engagement window; below-average fire rate; only available at energy 8+. | AB29: The Carbine is a specialist weapon for aggressive mechs that close distance fast. Lacks heavily in damage. | AC29: 7500 | AD29: A-Coins | AE29: legendary_weapon_12
A30: W029 | B30: Charge Rocket 6 | C30: Charge Rocket | D30: Legendary | E30: Missile | F30: S | G30: 6 | H30: 150 rpm | I30: 5 | J30: 0.4s per rocket | K30: 0–80m | L30: 80m | M30: Whirlwind | N30: Fires 1–5 rockets in quick succession, depending on charge time. Reload Speed is faster if fewer rockets are fired. If 5 rockets are charged, holding the fire button will increase your aim speed. Firing all 5 rockets will grant your Mech a temporary Speed Boost. | O30: Charges over 2s | T30: ~1,353 | U30: 1 | W30: 4 | Y30: 5 | Z30: Highest DPS/Energy in the missile category by a wide margin; Speed Boost on full release enables aggressive kite-in kite-out play; partial charge allows faster reloads when fewer rockets are needed. | AA30: 80m max range — shortest in the entire missile category; requires holding charge to maximise output; loses value if forced into long-range engagements. | AB30: Category benchmark by raw output. Near-instant 5-rocket burst at 150rpm followed by a 2s total reload gives sustained DPS no other missile approaches. The Speed Boost on full release adds mobility that makes the 80m range manageable on fast mechs. S-tier through sheer damage efficiency — the range cap is the only real constraint. | AC30: 600000 | AD30: Credits | AE30: legendary_weapon_6
A31: W030 | B31: Charge Rocket 8 | C31: Charge Rocket | D31: Legendary | E31: Missile | F31: S | G31: 8 | H31: 150 rpm | I31: 5 | J31: 0.4s per rocket | K31: 0–80m | L31: 80m | M31: Whirlwind | N31: Fires 1–5 rockets in quick succession, depending on charge time. Reload Speed is faster if fewer rockets are fired. If 5 rockets are charged, holding the fire button will increase your aim speed. Firing all 5 rockets will grant your Mech a temporary Speed Boost. | O31: Charges over 2s | T31: ~1,353 | U31: 1 | W31: 4 | Y31: 5 | Z31: Highest DPS/Energy in the missile category by a wide margin; Speed Boost on full release enables aggressive kite-in kite-out play; partial charge allows faster reloads when fewer rockets are needed. | AA31: 80m max range — shortest in the entire missile category; requires holding charge to maximise output; loses value if forced into long-range engagements. | AB31: Category benchmark by raw output. Near-instant 5-rocket burst at 150rpm followed by a 2s total reload gives sustained DPS no other missile approaches. The Speed Boost on full release adds mobility that makes the 80m range manageable on fast mechs. S-tier through sheer damage efficiency — the range cap is the only real constraint. | AC31: 7000 | AD31: A-Coins | AE31: legendary_weapon_8
